2024-03-12 18:59:14,441 INFO    StreamThr :31515 [internal.py:wandb_internal():86] W&B internal server running at pid: 31515, started at: 2024-03-12 18:59:14.441029
2024-03-12 18:59:14,442 DEBUG   HandlerThread:31515 [handler.py:handle_request():146] handle_request: status
2024-03-12 18:59:14,443 INFO    WriterThread:31515 [datastore.py:open_for_write():87] open: /home/labicquette/M1/intro-to-nlp-Nantes/projet-nlp-Nantes/wandb/run-20240312_185914-x97a4hl9/run-x97a4hl9.wandb
2024-03-12 18:59:14,443 DEBUG   SenderThread:31515 [sender.py:send():382] send: header
2024-03-12 18:59:14,444 DEBUG   SenderThread:31515 [sender.py:send():382] send: run
2024-03-12 18:59:19,445 DEBUG   HandlerThread:31515 [handler.py:handle_request():146] handle_request: keepalive
2024-03-12 18:59:24,446 DEBUG   HandlerThread:31515 [handler.py:handle_request():146] handle_request: keepalive
2024-03-12 18:59:29,447 DEBUG   HandlerThread:31515 [handler.py:handle_request():146] handle_request: keepalive
2024-03-12 18:59:34,448 DEBUG   HandlerThread:31515 [handler.py:handle_request():146] handle_request: keepalive
2024-03-12 18:59:39,449 DEBUG   HandlerThread:31515 [handler.py:handle_request():146] handle_request: keepalive
2024-03-12 18:59:44,450 DEBUG   HandlerThread:31515 [handler.py:handle_request():146] handle_request: keepalive
2024-03-12 18:59:47,788 INFO    SenderThread:31515 [retry.py:__call__():172] Retry attempt failed:
Traceback (most recent call last):
  File "/home/labicquette/.local/lib/python3.10/site-packages/urllib3/connection.py", line 203, in _new_conn
    sock = connection.create_connection(
  File "/home/labicquette/.local/lib/python3.10/site-packages/urllib3/util/connection.py", line 60, in create_connection
    for res in socket.getaddrinfo(host, port, family, socket.SOCK_STREAM):
  File "/usr/lib/python3.10/socket.py", line 955, in getaddrinfo
    for res in _socket.getaddrinfo(host, port, family, type, proto, flags):
socket.gaierror: [Errno -3] Temporary failure in name resolution

The above exception was the direct cause of the following exception:

Traceback (most recent call last):
  File "/home/labicquette/.local/lib/python3.10/site-packages/urllib3/connectionpool.py", line 791, in urlopen
    response = self._make_request(
  File "/home/labicquette/.local/lib/python3.10/site-packages/urllib3/connectionpool.py", line 492, in _make_request
    raise new_e
  File "/home/labicquette/.local/lib/python3.10/site-packages/urllib3/connectionpool.py", line 468, in _make_request
    self._validate_conn(conn)
  File "/home/labicquette/.local/lib/python3.10/site-packages/urllib3/connectionpool.py", line 1097, in _validate_conn
    conn.connect()
  File "/home/labicquette/.local/lib/python3.10/site-packages/urllib3/connection.py", line 611, in connect
    self.sock = sock = self._new_conn()
  File "/home/labicquette/.local/lib/python3.10/site-packages/urllib3/connection.py", line 210, in _new_conn
    raise NameResolutionError(self.host, self, e) from e
urllib3.exceptions.NameResolutionError: <urllib3.connection.HTTPSConnection object at 0x7f2cec647550>: Failed to resolve 'api.wandb.ai' ([Errno -3] Temporary failure in name resolution)

The above exception was the direct cause of the following exception:

Traceback (most recent call last):
  File "/home/labicquette/.local/lib/python3.10/site-packages/requests/adapters.py", line 486, in send
    resp = conn.urlopen(
  File "/home/labicquette/.local/lib/python3.10/site-packages/urllib3/connectionpool.py", line 845, in urlopen
    retries = retries.increment(
  File "/home/labicquette/.local/lib/python3.10/site-packages/urllib3/util/retry.py", line 515, in increment
    raise MaxRetryError(_pool, url, reason) from reason  # type: ignore[arg-type]
urllib3.exceptions.MaxRetryError: HTTPSConnectionPool(host='api.wandb.ai', port=443): Max retries exceeded with url: /graphql (Caused by NameResolutionError("<urllib3.connection.HTTPSConnection object at 0x7f2cec647550>: Failed to resolve 'api.wandb.ai' ([Errno -3] Temporary failure in name resolution)"))

During handling of the above exception, another exception occurred:

Traceback (most recent call last):
  File "/home/labicquette/.local/lib/python3.10/site-packages/wandb/sdk/lib/retry.py", line 131, in __call__
    result = self._call_fn(*args, **kwargs)
  File "/home/labicquette/.local/lib/python3.10/site-packages/wandb/sdk/internal/internal_api.py", line 369, in execute
    return self.client.execute(*args, **kwargs)  # type: ignore
  File "/home/labicquette/.local/lib/python3.10/site-packages/wandb/vendor/gql-0.2.0/wandb_gql/client.py", line 52, in execute
    result = self._get_result(document, *args, **kwargs)
  File "/home/labicquette/.local/lib/python3.10/site-packages/wandb/vendor/gql-0.2.0/wandb_gql/client.py", line 60, in _get_result
    return self.transport.execute(document, *args, **kwargs)
  File "/home/labicquette/.local/lib/python3.10/site-packages/wandb/sdk/lib/gql_request.py", line 58, in execute
    request = self.session.post(self.url, **post_args)
  File "/home/labicquette/.local/lib/python3.10/site-packages/requests/sessions.py", line 637, in post
    return self.request("POST", url, data=data, json=json, **kwargs)
  File "/home/labicquette/.local/lib/python3.10/site-packages/requests/sessions.py", line 589, in request
    resp = self.send(prep, **send_kwargs)
  File "/home/labicquette/.local/lib/python3.10/site-packages/requests/sessions.py", line 703, in send
    r = adapter.send(request, **kwargs)
  File "/home/labicquette/.local/lib/python3.10/site-packages/requests/adapters.py", line 519, in send
    raise ConnectionError(e, request=request)
requests.exceptions.ConnectionError: HTTPSConnectionPool(host='api.wandb.ai', port=443): Max retries exceeded with url: /graphql (Caused by NameResolutionError("<urllib3.connection.HTTPSConnection object at 0x7f2cec647550>: Failed to resolve 'api.wandb.ai' ([Errno -3] Temporary failure in name resolution)"))
2024-03-12 18:59:49,451 DEBUG   HandlerThread:31515 [handler.py:handle_request():146] handle_request: keepalive
2024-03-12 18:59:54,452 DEBUG   HandlerThread:31515 [handler.py:handle_request():146] handle_request: keepalive
2024-03-12 18:59:59,453 DEBUG   HandlerThread:31515 [handler.py:handle_request():146] handle_request: keepalive
2024-03-12 19:00:00,706 DEBUG   HandlerThread:31515 [handler.py:handle_request():146] handle_request: shutdown
2024-03-12 19:00:00,707 INFO    HandlerThread:31515 [handler.py:finish():869] shutting down handler
2024-03-12 19:00:01,449 INFO    WriterThread:31515 [datastore.py:close():296] close: /home/labicquette/M1/intro-to-nlp-Nantes/projet-nlp-Nantes/wandb/run-20240312_185914-x97a4hl9/run-x97a4hl9.wandb
2024-03-12 19:05:30,230 INFO    SenderThread:31515 [dir_watcher.py:__init__():211] watching files in: /home/labicquette/M1/intro-to-nlp-Nantes/projet-nlp-Nantes/wandb/run-20240312_185914-x97a4hl9/files
2024-03-12 19:05:30,230 INFO    SenderThread:31515 [sender.py:_start_run_threads():1136] run started: x97a4hl9 with start time 1710266354.441409
2024-03-12 19:05:30,230 INFO    SenderThread:31515 [sender.py:finish():1572] shutting down sender
2024-03-12 19:05:30,230 INFO    SenderThread:31515 [dir_watcher.py:finish():358] shutting down directory watcher
2024-03-12 19:05:31,230 INFO    SenderThread:31515 [dir_watcher.py:finish():388] scan: /home/labicquette/M1/intro-to-nlp-Nantes/projet-nlp-Nantes/wandb/run-20240312_185914-x97a4hl9/files
2024-03-12 19:05:31,230 INFO    SenderThread:31515 [dir_watcher.py:finish():402] scan save: /home/labicquette/M1/intro-to-nlp-Nantes/projet-nlp-Nantes/wandb/run-20240312_185914-x97a4hl9/files/config.yaml config.yaml
2024-03-12 19:05:31,230 INFO    SenderThread:31515 [file_pusher.py:finish():175] shutting down file pusher
2024-03-12 19:05:31,230 INFO    SenderThread:31515 [file_pusher.py:join():181] waiting for file pusher
2024-03-12 19:05:31,768 INFO    wandb-upload_0:31515 [upload_job.py:push():131] Uploaded file /home/labicquette/M1/intro-to-nlp-Nantes/projet-nlp-Nantes/wandb/run-20240312_185914-x97a4hl9/files/config.yaml
2024-03-12 19:05:32,232 INFO    SenderThread:31515 [file_stream.py:finish():595] file stream finish called
2024-03-12 19:05:32,438 INFO    SenderThread:31515 [file_stream.py:finish():599] file stream finish is done
